Traceback (most recent call last):
  File "/home/btb/anaconda3/envs/jbook/lib/python3.9/site-packages/jupyter_cache/executors/utils.py", line 51, in single_nb_execution
    executenb(
  File "/home/btb/anaconda3/envs/jbook/lib/python3.9/site-packages/nbclient/client.py", line 1093, in execute
    return NotebookClient(nb=nb, resources=resources, km=km, **kwargs).execute()
  File "/home/btb/anaconda3/envs/jbook/lib/python3.9/site-packages/nbclient/util.py", line 84, in wrapped
    return just_run(coro(*args, **kwargs))
  File "/home/btb/anaconda3/envs/jbook/lib/python3.9/site-packages/nbclient/util.py", line 62, in just_run
    return loop.run_until_complete(coro)
  File "/home/btb/anaconda3/envs/jbook/lib/python3.9/asyncio/base_events.py", line 642, in run_until_complete
    return future.result()
  File "/home/btb/anaconda3/envs/jbook/lib/python3.9/site-packages/nbclient/client.py", line 559, in async_execute
    await self.async_execute_cell(
  File "/home/btb/anaconda3/envs/jbook/lib/python3.9/site-packages/nbclient/client.py", line 854, in async_execute_cell
    self._check_raise_for_error(cell, exec_reply)
  File "/home/btb/anaconda3/envs/jbook/lib/python3.9/site-packages/nbclient/client.py", line 756, in _check_raise_for_error
    raise CellExecutionError.from_cell_and_msg(cell, exec_reply_content)
nbclient.exceptions.CellExecutionError: An error occurred while executing the following cell:
------------------
from tensorflow.keras.datasets import mnist

(train_images, train_labels), (test_images, test_labels) = mnist.load_data()
print(f"train images shape: {train_images.shape}")
print(f"train labels shape: {train_labels.shape}")
print(f"image shape: {train_images[0].shape}")
print(f"type of image: {type(train_images[0])}")
print(f"type of label: {type(train_labels[0])}")
------------------

[0;31m---------------------------------------------------------------------------[0m
[0;31mModuleNotFoundError[0m                       Traceback (most recent call last)
[0;32m/tmp/ipykernel_15704/2094881056.py[0m in [0;36m<module>[0;34m[0m
[0;32m----> 1[0;31m [0;32mfrom[0m [0mtensorflow[0m[0;34m.[0m[0mkeras[0m[0;34m.[0m[0mdatasets[0m [0;32mimport[0m [0mmnist[0m[0;34m[0m[0;34m[0m[0m
[0m[1;32m      2[0m [0;34m[0m[0m
[1;32m      3[0m [0;34m([0m[0mtrain_images[0m[0;34m,[0m [0mtrain_labels[0m[0;34m)[0m[0;34m,[0m [0;34m([0m[0mtest_images[0m[0;34m,[0m [0mtest_labels[0m[0;34m)[0m [0;34m=[0m [0mmnist[0m[0;34m.[0m[0mload_data[0m[0;34m([0m[0;34m)[0m[0;34m[0m[0;34m[0m[0m
[1;32m      4[0m [0mprint[0m[0;34m([0m[0;34mf"train images shape: {train_images.shape}"[0m[0;34m)[0m[0;34m[0m[0;34m[0m[0m
[1;32m      5[0m [0mprint[0m[0;34m([0m[0;34mf"train labels shape: {train_labels.shape}"[0m[0;34m)[0m[0;34m[0m[0;34m[0m[0m

[0;31mModuleNotFoundError[0m: No module named 'tensorflow'
ModuleNotFoundError: No module named 'tensorflow'

